{
	"id": 128462567,
	"body": "I appreciate your point, and I apologize for the confusion, but we can't update the docs for every possible confusion, and I haven't seen this come up much. \n\nAs Ian points out, the blog post already does state that recover only applies to panics in the current goroutine.\n\nRegarding try/catch, contrasting with those would require assuming that readers know those details, which is something we'd rather not do - many will not. But perhaps more importantly, I'm not aware of any language in which try/catch handles exceptions in \"child\" threads. Certainly in C++, Java, and Python exception catching is limited to the current thread. So that's not actually a contrast.",
	"user": {
		"login": "rsc",
		"id": 104030,
		"type": "User",
		"site_admin": false
	},
	"created_at": "2015-08-06T18:11:31Z",
	"updated_at": "2015-08-06T18:11:31Z"
}
