{
	"id": 240504382,
	"body": "Line is from here: https://github.com/docker/docker/blob/v1.11.2/vendor/src/github.com/docker/libnetwork/resolver.go#L355\r\n\r\nAFAICT the panic is happening from the defer Unlock in sync.Once.\r\nI cannot easily reproduce, this would be the first time I've seen such a panic.",
	"user": {
		"login": "cpuguy83",
		"id": 799078,
		"type": "User",
		"site_admin": false
	},
	"created_at": "2016-08-17T18:31:44Z",
	"updated_at": "2016-08-17T18:31:44Z"
}
